[2023-07-31 13:05:37,599] {taskinstance.py:1159} INFO - Dependencies all met for <TaskInstance: load_data_from_s3.load_data_task scheduled__2023-03-01T00:00:00+00:00 [queued]>
[2023-07-31 13:05:37,610] {taskinstance.py:1159} INFO - Dependencies all met for <TaskInstance: load_data_from_s3.load_data_task scheduled__2023-03-01T00:00:00+00:00 [queued]>
[2023-07-31 13:05:37,610] {taskinstance.py:1356} INFO - 
--------------------------------------------------------------------------------
[2023-07-31 13:05:37,610] {taskinstance.py:1357} INFO - Starting attempt 1 of 2
[2023-07-31 13:05:37,610] {taskinstance.py:1358} INFO - 
--------------------------------------------------------------------------------
[2023-07-31 13:05:37,656] {taskinstance.py:1377} INFO - Executing <Task(PythonOperator): load_data_task> on 2023-03-01 00:00:00+00:00
[2023-07-31 13:05:37,661] {standard_task_runner.py:52} INFO - Started process 3013 to run task
[2023-07-31 13:05:37,665] {standard_task_runner.py:79} INFO - Running: ['***', 'tasks', 'run', 'load_data_from_s3', 'load_data_task', 'scheduled__2023-03-01T00:00:00+00:00', '--job-id', '124', '--raw', '--subdir', 'DAGS_FOLDER/dag.py', '--cfg-path', '/tmp/tmpmvau81nk', '--error-file', '/tmp/tmpk78mamfu']
[2023-07-31 13:05:37,665] {standard_task_runner.py:80} INFO - Job 124: Subtask load_data_task
[2023-07-31 13:05:37,746] {task_command.py:370} INFO - Running <TaskInstance: load_data_from_s3.load_data_task scheduled__2023-03-01T00:00:00+00:00 [running]> on host 8aac46936356
[2023-07-31 13:05:37,936] {taskinstance.py:1571} INFO - Exporting the following env vars:
AIRFLOW_CTX_DAG_OWNER=***
AIRFLOW_CTX_DAG_ID=load_data_from_s3
AIRFLOW_CTX_TASK_ID=load_data_task
AIRFLOW_CTX_EXECUTION_DATE=2023-03-01T00:00:00+00:00
AIRFLOW_CTX_TRY_NUMBER=1
AIRFLOW_CTX_DAG_RUN_ID=scheduled__2023-03-01T00:00:00+00:00
[2023-07-31 13:05:37,948] {base.py:68} INFO - Using connection ID 'aws_default' for task execution.
[2023-07-31 13:05:37,948] {base_aws.py:206} INFO - Credentials retrieved from login
[2023-07-31 13:05:38,187] {taskinstance.py:1889} ERROR - Task failed with exception
Traceback (most recent call last):
  File "/home/airflow/.local/lib/python3.7/site-packages/airflow/operators/python.py", line 171, in execute
    return_value = self.execute_callable()
  File "/home/airflow/.local/lib/python3.7/site-packages/airflow/operators/python.py", line 189, in execute_callable
    return self.python_callable(*self.op_args, **self.op_kwargs)
  File "/opt/airflow/dags/dag.py", line 18, in load_data_from_s3
    s3_object = s3_hook.get_key(bucket_name=s3_bucket, key=s3_key)
  File "/home/airflow/.local/lib/python3.7/site-packages/airflow/providers/amazon/aws/hooks/s3.py", line 63, in wrapper
    return func(*bound_args.args, **bound_args.kwargs)
  File "/home/airflow/.local/lib/python3.7/site-packages/airflow/providers/amazon/aws/hooks/s3.py", line 91, in wrapper
    return func(*bound_args.args, **bound_args.kwargs)
  File "/home/airflow/.local/lib/python3.7/site-packages/airflow/providers/amazon/aws/hooks/s3.py", line 466, in get_key
    obj.load()
  File "/home/airflow/.local/lib/python3.7/site-packages/boto3/resources/factory.py", line 564, in do_action
    response = action(self, *args, **kwargs)
  File "/home/airflow/.local/lib/python3.7/site-packages/boto3/resources/action.py", line 88, in __call__
    response = getattr(parent.meta.client, operation_name)(*args, **params)
  File "/home/airflow/.local/lib/python3.7/site-packages/botocore/client.py", line 508, in _api_call
    return self._make_api_call(operation_name, kwargs)
  File "/home/airflow/.local/lib/python3.7/site-packages/botocore/client.py", line 911, in _make_api_call
    raise error_class(parsed_response, operation_name)
botocore.exceptions.ClientError: An error occurred (403) when calling the HeadObject operation: Forbidden
[2023-07-31 13:05:38,202] {taskinstance.py:1400} INFO - Marking task as UP_FOR_RETRY. dag_id=load_data_from_s3, task_id=load_data_task, execution_date=20230301T000000, start_date=20230731T130537, end_date=20230731T130538
[2023-07-31 13:05:38,304] {standard_task_runner.py:97} ERROR - Failed to execute job 124 for task load_data_task (An error occurred (403) when calling the HeadObject operation: Forbidden; 3013)
[2023-07-31 13:05:38,320] {local_task_job.py:156} INFO - Task exited with return code 1
[2023-07-31 13:05:38,437] {local_task_job.py:273} INFO - 0 downstream tasks scheduled from follow-on schedule check
