[2023-08-02 07:16:50,750] {taskinstance.py:1159} INFO - Dependencies all met for <TaskInstance: s3_to_postgres.load_weather_data manual__2023-08-02T07:16:48.814960+00:00 [queued]>
[2023-08-02 07:16:50,759] {taskinstance.py:1159} INFO - Dependencies all met for <TaskInstance: s3_to_postgres.load_weather_data manual__2023-08-02T07:16:48.814960+00:00 [queued]>
[2023-08-02 07:16:50,759] {taskinstance.py:1356} INFO - 
--------------------------------------------------------------------------------
[2023-08-02 07:16:50,759] {taskinstance.py:1357} INFO - Starting attempt 1 of 2
[2023-08-02 07:16:50,759] {taskinstance.py:1358} INFO - 
--------------------------------------------------------------------------------
[2023-08-02 07:16:50,785] {taskinstance.py:1377} INFO - Executing <Task(PythonOperator): load_weather_data> on 2023-08-02 07:16:48.814960+00:00
[2023-08-02 07:16:50,791] {standard_task_runner.py:52} INFO - Started process 3931 to run task
[2023-08-02 07:16:50,793] {standard_task_runner.py:79} INFO - Running: ['***', 'tasks', 'run', 's3_to_postgres', 'load_weather_data', 'manual__2023-08-02T07:16:48.814960+00:00', '--job-id', '240', '--raw', '--subdir', 'DAGS_FOLDER/dag.py', '--cfg-path', '/tmp/tmpop3g1xmx', '--error-file', '/tmp/tmp1il2g_gz']
[2023-08-02 07:16:50,794] {standard_task_runner.py:80} INFO - Job 240: Subtask load_weather_data
[2023-08-02 07:16:50,845] {task_command.py:370} INFO - Running <TaskInstance: s3_to_postgres.load_weather_data manual__2023-08-02T07:16:48.814960+00:00 [running]> on host 656341a29da6
[2023-08-02 07:16:50,931] {taskinstance.py:1571} INFO - Exporting the following env vars:
AIRFLOW_CTX_DAG_OWNER=***
AIRFLOW_CTX_DAG_ID=s3_to_postgres
AIRFLOW_CTX_TASK_ID=load_weather_data
AIRFLOW_CTX_EXECUTION_DATE=2023-08-02T07:16:48.814960+00:00
AIRFLOW_CTX_TRY_NUMBER=1
AIRFLOW_CTX_DAG_RUN_ID=manual__2023-08-02T07:16:48.814960+00:00
[2023-08-02 07:16:51,422] {logging_mixin.py:115} INFO - 
DATAFRAME SHAPE : (13, 10)
[2023-08-02 07:16:51,423] {logging_mixin.py:115} INFO - 
✅ DataFrame created ! ✅
[2023-08-02 07:16:51,783] {logging_mixin.py:115} INFO - Error: Could not create the table because it already exists. Change the if_exists parameter to 'append' or 'replace' data.
[2023-08-02 07:16:51,786] {python.py:173} INFO - Done. Returned value was: None
[2023-08-02 07:16:52,337] {taskinstance.py:1400} INFO - Marking task as SUCCESS. dag_id=s3_to_postgres, task_id=load_weather_data, execution_date=20230802T071648, start_date=20230802T071650, end_date=20230802T071652
[2023-08-02 07:16:52,412] {local_task_job.py:156} INFO - Task exited with return code 0
[2023-08-02 07:16:52,465] {local_task_job.py:273} INFO - 0 downstream tasks scheduled from follow-on schedule check
