[2023-08-02 13:54:18,315] {taskinstance.py:1159} INFO - Dependencies all met for <TaskInstance: S3_to_BigQuery.cleaning_weather_data manual__2023-08-02T13:54:06.195305+00:00 [queued]>
[2023-08-02 13:54:18,323] {taskinstance.py:1159} INFO - Dependencies all met for <TaskInstance: S3_to_BigQuery.cleaning_weather_data manual__2023-08-02T13:54:06.195305+00:00 [queued]>
[2023-08-02 13:54:18,323] {taskinstance.py:1356} INFO - 
--------------------------------------------------------------------------------
[2023-08-02 13:54:18,324] {taskinstance.py:1357} INFO - Starting attempt 1 of 2
[2023-08-02 13:54:18,324] {taskinstance.py:1358} INFO - 
--------------------------------------------------------------------------------
[2023-08-02 13:54:18,349] {taskinstance.py:1377} INFO - Executing <Task(PythonOperator): cleaning_weather_data> on 2023-08-02 13:54:06.195305+00:00
[2023-08-02 13:54:18,354] {standard_task_runner.py:52} INFO - Started process 2857 to run task
[2023-08-02 13:54:18,356] {standard_task_runner.py:79} INFO - Running: ['***', 'tasks', 'run', 'S3_to_BigQuery', 'cleaning_weather_data', 'manual__2023-08-02T13:54:06.195305+00:00', '--job-id', '398', '--raw', '--subdir', 'DAGS_FOLDER/dag.py', '--cfg-path', '/tmp/tmp7x895mt6', '--error-file', '/tmp/tmp7zk_yk0t']
[2023-08-02 13:54:18,357] {standard_task_runner.py:80} INFO - Job 398: Subtask cleaning_weather_data
[2023-08-02 13:54:18,416] {task_command.py:370} INFO - Running <TaskInstance: S3_to_BigQuery.cleaning_weather_data manual__2023-08-02T13:54:06.195305+00:00 [running]> on host f57ce474b9bb
[2023-08-02 13:54:18,496] {taskinstance.py:1571} INFO - Exporting the following env vars:
AIRFLOW_CTX_DAG_OWNER=***
AIRFLOW_CTX_DAG_ID=S3_to_BigQuery
AIRFLOW_CTX_TASK_ID=cleaning_weather_data
AIRFLOW_CTX_EXECUTION_DATE=2023-08-02T13:54:06.195305+00:00
AIRFLOW_CTX_TRY_NUMBER=1
AIRFLOW_CTX_DAG_RUN_ID=manual__2023-08-02T13:54:06.195305+00:00
[2023-08-02 13:54:18,508] {logging_mixin.py:115} INFO - 
DataFrame push into xcom.
[2023-08-02 13:54:18,509] {logging_mixin.py:115} INFO - Error: 'datetime'
[2023-08-02 13:54:18,509] {python.py:173} INFO - Done. Returned value was: None
[2023-08-02 13:54:18,523] {taskinstance.py:1400} INFO - Marking task as SUCCESS. dag_id=S3_to_BigQuery, task_id=cleaning_weather_data, execution_date=20230802T135406, start_date=20230802T135418, end_date=20230802T135418
[2023-08-02 13:54:18,568] {local_task_job.py:156} INFO - Task exited with return code 0
[2023-08-02 13:54:18,622] {local_task_job.py:273} INFO - 1 downstream tasks scheduled from follow-on schedule check
