[2023-08-02 08:41:42,457] {taskinstance.py:1159} INFO - Dependencies all met for <TaskInstance: S3_to_BigQuery.load_stations_data manual__2023-08-02T08:41:39.138305+00:00 [queued]>
[2023-08-02 08:41:42,466] {taskinstance.py:1159} INFO - Dependencies all met for <TaskInstance: S3_to_BigQuery.load_stations_data manual__2023-08-02T08:41:39.138305+00:00 [queued]>
[2023-08-02 08:41:42,466] {taskinstance.py:1356} INFO - 
--------------------------------------------------------------------------------
[2023-08-02 08:41:42,466] {taskinstance.py:1357} INFO - Starting attempt 1 of 2
[2023-08-02 08:41:42,466] {taskinstance.py:1358} INFO - 
--------------------------------------------------------------------------------
[2023-08-02 08:41:42,525] {taskinstance.py:1377} INFO - Executing <Task(PythonOperator): load_stations_data> on 2023-08-02 08:41:39.138305+00:00
[2023-08-02 08:41:42,531] {standard_task_runner.py:52} INFO - Started process 7890 to run task
[2023-08-02 08:41:42,534] {standard_task_runner.py:79} INFO - Running: ['***', 'tasks', 'run', 'S3_to_BigQuery', 'load_stations_data', 'manual__2023-08-02T08:41:39.138305+00:00', '--job-id', '269', '--raw', '--subdir', 'DAGS_FOLDER/dag.py', '--cfg-path', '/tmp/tmpi0erws_q', '--error-file', '/tmp/tmpn32zv3kl']
[2023-08-02 08:41:42,535] {standard_task_runner.py:80} INFO - Job 269: Subtask load_stations_data
[2023-08-02 08:41:42,656] {task_command.py:370} INFO - Running <TaskInstance: S3_to_BigQuery.load_stations_data manual__2023-08-02T08:41:39.138305+00:00 [running]> on host 656341a29da6
[2023-08-02 08:41:42,742] {taskinstance.py:1571} INFO - Exporting the following env vars:
AIRFLOW_CTX_DAG_OWNER=***
AIRFLOW_CTX_DAG_ID=S3_to_BigQuery
AIRFLOW_CTX_TASK_ID=load_stations_data
AIRFLOW_CTX_EXECUTION_DATE=2023-08-02T08:41:39.138305+00:00
AIRFLOW_CTX_TRY_NUMBER=1
AIRFLOW_CTX_DAG_RUN_ID=manual__2023-08-02T08:41:39.138305+00:00
[2023-08-02 08:41:42,743] {taskinstance.py:1889} ERROR - Task failed with exception
Traceback (most recent call last):
  File "/home/airflow/.local/lib/python3.7/site-packages/airflow/operators/python.py", line 171, in execute
    return_value = self.execute_callable()
  File "/home/airflow/.local/lib/python3.7/site-packages/airflow/operators/python.py", line 189, in execute_callable
    return self.python_callable(*self.op_args, **self.op_kwargs)
  File "/opt/airflow/dags/dag.py", line 19, in load_stations_data
    return s3_load('lime-api','lime_stations_topic')
TypeError: s3_load() missing 1 required positional argument: 'ti'
[2023-08-02 08:41:42,750] {taskinstance.py:1400} INFO - Marking task as UP_FOR_RETRY. dag_id=S3_to_BigQuery, task_id=load_stations_data, execution_date=20230802T084139, start_date=20230802T084142, end_date=20230802T084142
[2023-08-02 08:41:42,779] {standard_task_runner.py:97} ERROR - Failed to execute job 269 for task load_stations_data (s3_load() missing 1 required positional argument: 'ti'; 7890)
[2023-08-02 08:41:42,786] {local_task_job.py:156} INFO - Task exited with return code 1
[2023-08-02 08:41:42,841] {local_task_job.py:273} INFO - 0 downstream tasks scheduled from follow-on schedule check
