[2023-07-31 12:49:49,424] {taskinstance.py:1159} INFO - Dependencies all met for <TaskInstance: load_data_from_s3.load_data_task scheduled__2023-01-07T00:00:00+00:00 [queued]>
[2023-07-31 12:49:49,438] {taskinstance.py:1159} INFO - Dependencies all met for <TaskInstance: load_data_from_s3.load_data_task scheduled__2023-01-07T00:00:00+00:00 [queued]>
[2023-07-31 12:49:49,438] {taskinstance.py:1356} INFO - 
--------------------------------------------------------------------------------
[2023-07-31 12:49:49,438] {taskinstance.py:1357} INFO - Starting attempt 1 of 2
[2023-07-31 12:49:49,438] {taskinstance.py:1358} INFO - 
--------------------------------------------------------------------------------
[2023-07-31 12:49:49,482] {taskinstance.py:1377} INFO - Executing <Task(PythonOperator): load_data_task> on 2023-01-07 00:00:00+00:00
[2023-07-31 12:49:49,487] {standard_task_runner.py:52} INFO - Started process 2100 to run task
[2023-07-31 12:49:49,489] {standard_task_runner.py:79} INFO - Running: ['***', 'tasks', 'run', 'load_data_from_s3', 'load_data_task', 'scheduled__2023-01-07T00:00:00+00:00', '--job-id', '22', '--raw', '--subdir', 'DAGS_FOLDER/dag.py', '--cfg-path', '/tmp/tmpc1p9rc7e', '--error-file', '/tmp/tmpi9b0jil_']
[2023-07-31 12:49:49,490] {standard_task_runner.py:80} INFO - Job 22: Subtask load_data_task
[2023-07-31 12:49:49,554] {task_command.py:370} INFO - Running <TaskInstance: load_data_from_s3.load_data_task scheduled__2023-01-07T00:00:00+00:00 [running]> on host 8aac46936356
[2023-07-31 12:49:49,682] {taskinstance.py:1571} INFO - Exporting the following env vars:
AIRFLOW_CTX_DAG_OWNER=***
AIRFLOW_CTX_DAG_ID=load_data_from_s3
AIRFLOW_CTX_TASK_ID=load_data_task
AIRFLOW_CTX_EXECUTION_DATE=2023-01-07T00:00:00+00:00
AIRFLOW_CTX_TRY_NUMBER=1
AIRFLOW_CTX_DAG_RUN_ID=scheduled__2023-01-07T00:00:00+00:00
[2023-07-31 12:49:49,695] {base_aws.py:447} WARNING - Unable to use Airflow Connection for credentials.
[2023-07-31 12:49:51,699] {taskinstance.py:1889} ERROR - Task failed with exception
Traceback (most recent call last):
  File "/home/airflow/.local/lib/python3.7/site-packages/airflow/operators/python.py", line 171, in execute
    return_value = self.execute_callable()
  File "/home/airflow/.local/lib/python3.7/site-packages/airflow/operators/python.py", line 189, in execute_callable
    return self.python_callable(*self.op_args, **self.op_kwargs)
  File "/opt/airflow/dags/dag.py", line 15, in load_data_from_s3
    s3_object = s3_hook.get_key(bucket_name=s3_bucket, key=s3_key)
  File "/home/airflow/.local/lib/python3.7/site-packages/airflow/providers/amazon/aws/hooks/s3.py", line 63, in wrapper
    return func(*bound_args.args, **bound_args.kwargs)
  File "/home/airflow/.local/lib/python3.7/site-packages/airflow/providers/amazon/aws/hooks/s3.py", line 91, in wrapper
    return func(*bound_args.args, **bound_args.kwargs)
  File "/home/airflow/.local/lib/python3.7/site-packages/airflow/providers/amazon/aws/hooks/s3.py", line 466, in get_key
    obj.load()
  File "/home/airflow/.local/lib/python3.7/site-packages/boto3/resources/factory.py", line 564, in do_action
    response = action(self, *args, **kwargs)
  File "/home/airflow/.local/lib/python3.7/site-packages/boto3/resources/action.py", line 88, in __call__
    response = getattr(parent.meta.client, operation_name)(*args, **params)
  File "/home/airflow/.local/lib/python3.7/site-packages/botocore/client.py", line 508, in _api_call
    return self._make_api_call(operation_name, kwargs)
  File "/home/airflow/.local/lib/python3.7/site-packages/botocore/client.py", line 895, in _make_api_call
    operation_model, request_dict, request_context
  File "/home/airflow/.local/lib/python3.7/site-packages/botocore/client.py", line 917, in _make_request
    return self._endpoint.make_request(operation_model, request_dict)
  File "/home/airflow/.local/lib/python3.7/site-packages/botocore/endpoint.py", line 116, in make_request
    return self._send_request(request_dict, operation_model)
  File "/home/airflow/.local/lib/python3.7/site-packages/botocore/endpoint.py", line 195, in _send_request
    request = self.create_request(request_dict, operation_model)
  File "/home/airflow/.local/lib/python3.7/site-packages/botocore/endpoint.py", line 134, in create_request
    operation_name=operation_model.name,
  File "/home/airflow/.local/lib/python3.7/site-packages/botocore/hooks.py", line 412, in emit
    return self._emitter.emit(aliased_event_name, **kwargs)
  File "/home/airflow/.local/lib/python3.7/site-packages/botocore/hooks.py", line 256, in emit
    return self._emit(event_name, kwargs)
  File "/home/airflow/.local/lib/python3.7/site-packages/botocore/hooks.py", line 239, in _emit
    response = handler(**kwargs)
  File "/home/airflow/.local/lib/python3.7/site-packages/botocore/signers.py", line 103, in handler
    return self.sign(operation_name, request)
  File "/home/airflow/.local/lib/python3.7/site-packages/botocore/signers.py", line 187, in sign
    auth.add_auth(request)
  File "/home/airflow/.local/lib/python3.7/site-packages/botocore/auth.py", line 407, in add_auth
    raise NoCredentialsError()
botocore.exceptions.NoCredentialsError: Unable to locate credentials
[2023-07-31 12:49:51,710] {taskinstance.py:1400} INFO - Marking task as UP_FOR_RETRY. dag_id=load_data_from_s3, task_id=load_data_task, execution_date=20230107T000000, start_date=20230731T124949, end_date=20230731T124951
[2023-07-31 12:49:51,958] {standard_task_runner.py:97} ERROR - Failed to execute job 22 for task load_data_task (Unable to locate credentials; 2100)
[2023-07-31 12:49:51,988] {local_task_job.py:156} INFO - Task exited with return code 1
[2023-07-31 12:49:52,124] {local_task_job.py:273} INFO - 0 downstream tasks scheduled from follow-on schedule check
